<?xml version="1.0"?>
<robot xmlns:xacro="http://www.ros.org/wiki/xacro" >

    <xacro:include filename="inertial_macros.xacro"/>

    <material name="white">
        <color rgba="1 1 1 1" />
    </material>

    <material name="orange">
        <color rgba="1 0.3 0.1 1"/>
    </material>

    <material name="yellow">
        <color rgba="1 1 0 1"/>
    </material>

    <material name="blue">
        <color rgba="0.2 0.2 1 1"/>
    </material>

    <material name="black">
        <color rgba="0 0 0 1"/>
    </material>

    <material name="red">
        <color rgba="1 0 0 1"/>
    </material>

    <!-- BASE LINK -->

    <link name="base_link">

    </link>

    <!-- BASE_FOOTPRINT LINK -->

    <joint name="base_footprint_joint" type="fixed">
        <parent link="base_link"/>
        <child link="base_footprint"/>
        <origin xyz="0 0 0" rpy="0 0 0"/>
    </joint>

    <link name="base_footprint">
    </link>



    <!-- CHASSIS LINK -->

    <joint name="chassis_joint" type="fixed">
        <parent link="base_link"/>
        <child link="chassis"/>
        <origin xyz="-0.08 0 0"/>
    </joint>

    <link name="chassis">
        <visual>
            <origin xyz="0.08 0 0"/>
            <geometry>
                <mesh filename="file://$(find test_bot)/meshes/Chassis.stl" scale="0.001 0.001 0.001" />
                <!-- <mesh filename="$(find test_bot)/stl/Chassis.stl" scale="0.001 0.001 0.001" /> -->
            </geometry>
            <material name="black"/>
        </visual>

        <collision>
            <origin xyz="0.08 0 0"/>
            <geometry>
                <cylinder radius="0.08" length="0.003"/>
            </geometry>
        </collision>

        <!-- <inertial>
            <mass value="0.2"/>
            <origin xyz="0.18 0 -0.005" rpy="0 0 0"/>
            <inertia ixx="0.01" ixy="0" ixz="0" iyy="0.01" iyz="0" izz="0.01"/>
        </inertial> -->

        <xacro:inertial_cylinder mass="0.1" length="0.005" radius="0.08">
            <origin xyz="0.08 0 0" rpy="0 0 0"/>
        </xacro:inertial_cylinder>
    </link>

    <gazebo reference="chassis">
        <material>Gazebo/Black</material>
    </gazebo>
    
    <!-- LEFT WHEEL LINK -->

    <joint name="left_wheel_joint" type="continuous">
        <parent link="base_link"/>
        <child link="left_wheel"/>
        <origin xyz="0 0.09 0" rpy="-${pi/2} 0 0" />
        <axis xyz="0 0 1"/>
    </joint>

    <link name="left_wheel">
        <visual>
            <geometry>
                <cylinder radius="0.0325" length="0.02"/>
            </geometry>
            <material name="yellow"/>
        </visual>

        <collision>
            <geometry>
                <sphere radius="0.0325" />
            </geometry>
        </collision>

        <xacro:inertial_cylinder mass="0.1" length="0.02" radius="0.0325">
            <origin xyz="0 0 0" rpy="0 0 0"/>
        </xacro:inertial_cylinder>
    </link>

    <gazebo reference="left_wheel">
        <material>Gazebo/Yellow</material>
    </gazebo>

    <!-- RIGHT WHEEL LINK -->

    <joint name="right_wheel_joint" type="continuous">
        <parent link="base_link"/>
        <child link="right_wheel"/>
        <origin xyz="0 -0.09 0" rpy="${pi/2} 0 0" />
        <axis xyz="0 0 -1"/>
    </joint>

    <link name="right_wheel">
        <visual>
            <geometry>
                <cylinder radius="0.0325" length="0.02"/>
            </geometry>
            <material name="yellow"/>
        </visual>

        <collision>
            <geometry>
                <sphere radius="0.0325" />
            </geometry>
        </collision>

        <xacro:inertial_cylinder mass="0.1" length="0.02" radius="0.0325">
            <origin xyz="0 0 0" rpy="0 0 0"/>
        </xacro:inertial_cylinder>
    </link>

    <gazebo reference="right_wheel">
        <material>Gazebo/Yellow</material>
    </gazebo>

    <!-- CASTER WHEEL LINK -->

    <joint name="caster_wheel_joint" type="fixed">
        <parent link="chassis"/>
        <child link="caster_wheel"/>
        <origin xyz="0.14 0 -0.01625"/>
        <!-- <origin xyz="0.24 0 0"/> -->
    </joint>


    <link name="caster_wheel">
        <visual>
            <geometry>
                <sphere radius="0.01625"/>
            </geometry>
            <material name="white"/>
        </visual>
        <collision>
            <geometry>
                <sphere radius="0.01625"/>
            </geometry>
        </collision>
        <xacro:inertial_sphere mass="0.1" radius="0.01625">
            <origin xyz="0 0 0" rpy="0 0 0"/>
        </xacro:inertial_sphere>
    </link>

    <gazebo reference="caster_wheel">
        <material>Gazebo/White</material>
        <mu1 value="0.001"/>
        <mu2 value="0.001"/>
    </gazebo>
        
</robot>